Workbook
Name \a: #REF!
Name \a: '[1]01重点管理ｴﾘｱ'!#REF!
Name \b: [2]事務所引越見積書!#REF!
Name \c: #N/A
Name \p: #N/A
Name \p: '[1]01重点管理ｴﾘｱ'!#REF!
Name _____B888: [0]!_____B888
Name ____B888: [0]!____B888
Name ___B888: [0]!___B888
Name __B888: [0]!__B888
Name _2Module1__手段別__.ボタン13_Click: [9]!'[Module1 (手段別)].ボタン13_Click'
Name _2累積マクロ_.累積マクロ: [0]!_2累積マクロ_.累積マクロ
Name _3Module1__手段別__.ボタン13_Click: [9]!'[Module1 (手段別)].ボタン13_Click'
Name _3累積マクロ_.累積マクロ: [0]!_3累積マクロ_.累積マクロ
Name _４Ｓ: #REF!
Name _４Ｓ: #REF!
Name _4累積マクロ_.累積マクロ: [0]!_4累積マクロ_.累積マクロ
Name _5累積マクロ_.累積マクロ: [0]!_5累積マクロ_.累積マクロ
Name _6累積マクロ_.累積マクロ: [0]!_6累積マクロ_.累積マクロ
Name _72T内示: #REF!
Name _72T内示: #REF!
Name _7累積マクロ_.累積マクロ: [0]!_7累積マクロ_.累積マクロ
Name _B888: 'Front Page'!_B888
Name _B888: [0]!_B888
Name _n1: #REF!
Name _n1: #REF!
Name _n2: #REF!
Name _n2: #REF!
Name aa: 'Front Page'!aa
Name aa: [0]!aa
Name aaa: 'Front Page'!aaa
Name aaa: [0]!aaa
Name AAAAAA: 'Front Page'!AAAAAA
Name AAAAAA: [0]!AAAAAA
Name AM: #REF!
Name AM: #REF!
Name Arial: #REF!
Name Ａｓｓｙ: #REF!
Name Ａｓｓｙ: #REF!
Name Auditor: '[10]set date'!$B$5:$G$29
Name b: [11]納入総括!#REF!
Name BBB: 'Front Page'!BBB
Name BBB: [0]!BBB
Name BM_XRateEdit: [12]!BM_XRateEdit
Name BM_XRateEdit: [13]!BM_XRateEdit
Name carmaker: [14]Titel!$B$8
Name cel0jisiyousyomente: #REF!
Name cel11_Proposal_Clay: #REF!
Name cel11ikouankousousyo: #REF!
Name cel11ikouankousousyosyuuyaku: #REF!
Name cel1jikaisyuu: #REF!
Name cel1seisigettou: #REF!
Name celAgreement: #REF!
Name celALIAS: #REF!
Name celApplication: #REF!
Name celApplied_Consept_Document: #REF!
Name celApproval: #REF!
Name celBody_Styling_Fix: #REF!
Name celConfirmation: #REF!
Name celCost_DDC_Mtg: #REF!

Sheet Front Page
D3: 1 | E3: How to | L3: Control No.
D4: 2 | E4: Standard | L4: DOC-ARD-PDS-000
D5: 3 | E5: Check sheet
D6: 4 | E6: Format
D7: 5 | E7: Guide line
D8: ⑥ | E8: Project Document
D9: 7 | E9: Other :
D11: Project Design Specification Model : Project Name: HONDA MMCA BSI
C21: Contents | I21: Note / Related Document
C22: 1. Circuit Specification
C23: 2. Appendix
C24: 3. Estimate cost
C31: Revision History
C32: No. | D32: Change Date | F32: Cause | L32: Issued | N32: Approved
C33: N | D33: 45926 | F33: New | L33: Rattakiat Ch
C34: 1 | D34: 45897 | F34: Design PCB | L34: Rattakiat Ch
C35: 2 | D35: 45926 | F35: Update the new PCB shape, Design RH | L35: Rattakiat Ch
C36: 3 | D36: 45931 | F36: Update PCB shape | L36: Rattakiat Ch
C37: 4 | D37: 46072 | F37: Big PCB update, PCB shape and Layout | L37: Rattakiat Ch
C38: 5 | D38: 46087 | F38: PCB Layout Change | L38: Rattakiat Ch
C39: 6 | D39: 46098 | F39: PCB Layout Change | L39: Rattakiat Ch
C40: 7 | D40: 46169 | F40: Change LED P/N and C1,C2 P/N, Update new Gerber with LED layout change | L40: Rattakiat Ch
C41: 8 | D41: 46210 | F41: Edit Capacitor Part Number | L41: Rattakiat Ch
C42: 9 | D42: 46262 | F42: Add LED3 (3 LEDs in series), update schematic and PCB shape LH/RH Rev.09 | L42: Rattakiat Ch
C43: 10
C44: 11
C45: 12
C46: 13
C47: 14
C48: 15
J50: Issued | L50: Checked | N50: Approved
J51: In charge | L51: MG | N51: GM
J52: Rattakiat | L52: Krissada | N52: Imabeppu
C54: AMPAS R&D Co.,Ltd.
L57: Effective 07/01/2024
F58: Confidential : Property of AMPAS R&D Co.,Ltd. - Duplication prohibited | O58: Page.1

Sheet CIRCUIT SPECIFICATION
B1: CIRCUIT SPECIFICATION | G1: PRODUCT NAME | H1: HONDA MMCA BSI | I1: REVISION | K1: Rev.09 | L1: APPROVED BY | M1: CHECKED BY | N1: ISSUED BY
I2: ISSUED BY | K2: AMPAS R&D | L2: K.Imabeppu | M2: Krissada C. | N2: Rattakiat Ch.
I3: ISSUE DATE | K3: 46262
B4: Contents in this sheet is under consideration. Circuit spec have possibility to change. | I4: NAME | K4: CIRCUIT ASSY
I5: PURPOSE | K5: ESTIMATION
B7: 1. LOAD SPEC | F7: 5. PARTS LIST
B8: ITEMS | D8: CONTENTS | F8: REFERENCE NAME | G8: QTY | H8: NAME | I8: LEAD TYPE | J8: MANUFACTURER | K8: MODEL No. | L8: RATED VALUE | M8: REMARKS
B9: STYLE | D9: - | F9: C_BUS1, C9, C10 | G9: 3 | H9: CAPACITOR | I9: SMD | J9: TDK | K9: C1005X5R1E224M050BC | L9: 220nF/25V | M9: 0402; X5R; ±20%; RoHS
B10: MANUFACTURER | D10: - | F10: C_OUT1 - C_OUT5 | G10: 5 | H10: CAPACITOR | I10: SMD | J10: MURATA | K10: GRT31CR61E226KE01L | L10: 22µF/25V | M10: 1206 (3216); X5R; ±10%
B11: PART NUMBER | D11: - | F11: C1, C13 | G11: 2 | H11: CAPACITOR | I11: SMD | J11: KEMET | K11: EDH476M050S9HAA | L11: 47µF/50V | M11: Aluminum electrolytic; ±20%
B12: TOTAL QUANTITY | D12: - | F12: C2, C4, C6 | G12: 3 | H12: CAPACITOR | I12: SMD | J12: TDK | K12: CGA5L1X7R1H106K160AC | L12: 10µF/50V | M12: 1206; X7R; ±10%; +125°C; Auto
B13: FUNCTION | D13: - | F13: C3, C5, C7, C8 | G13: 4 | H13: CAPACITOR | I13: SMD | J13: TDK | K13: CGA3E2X7R1H104K080AA | L13: 100nF/50V | M13: 0603; X7R; ±10%; +125°C; Auto
B14: BIN OF LED | C14: BRIGHTNESS | D14: - | F14: C11 | G14: 1 | H14: CAPACITOR | I14: SMD | J14: MURATA | K14: GRT155R61E225KE13D | L14: 2.2µF/25V | M14: 0402; X5R; ±10%; RoHS
C15: WAVELENGTH | D15: - | F15: C12 | G15: 1 | H15: CAPACITOR | I15: SMD | J15: TDK | K15: CGA2B3X7R1E104K050BB | L15: 100nF/25V | M15: 0402; X7R; ±10%; +125°C; Auto
C16: FORWARD VOLTAGE | D16: - | F16: C14 | G16: 1 | H16: CAPACITOR | I16: SMD | J16: TDK | K16: CGA3E2X5R1A105K080AA | L16: 1µF/10V | M16: 0603; X5R; ±10%; +85°C; Auto
B17: NOTE | D17: - | F17: J2 | G17: 1 | H17: CONNECTOR | I17: SMD | J17: MOLEX | K17: 219320-0001 | L17: - | M17: USB Type-C; 16 circuits; vertical
F18: L_EMI1 | G18: 1 | H18: INDUCTOR | I18: SMD | J18: COILCRAFT | K18: XAL4020-102MEC | L18: 1µH/9.6A | M18: ±20%; DCR 14.60mΩ; AEC-Q200
B19: ITEMS | D19: CONTENTS | F19: L1 | G19: 1 | H19: INDUCTOR | I19: SMD | J19: COILCRAFT | K19: XAL6060-103MEB | L19: 10µH | M19: Shielded; ±20%; 29.82mΩ; AEC-Q200
B20: STYLE | D20: - | F20: NTC1 | G20: 1 | H20: THERMISTOR NTC | I20: SMD | J20: MURATA | K20: NCU18WF104F6SRB | L20: 100kΩ | M20: 0603; ±1%; NTC
B21: MANUFACTURER | D21: - | F21: R_BUS1 | G21: 1 | H21: RESISTOR | I21: SMD | J21: KOA SPEER | K21: RK73B2ATTD101J | L21: 100Ω | M21: Thick Film Resistors - SMD 100ohm 5%
B22: PART NUMBER | D22: - | F22: R_NTC1 | G22: 1 | H22: RESISTOR | I22: SMD | J22: KOA SPEER | K22: RK73H1ETTPD1002F | L22: 10kΩ/100mW | M22: 0402
B23: TOTAL QUANTITY | D23: - | F23: R_SENSE1 | G23: 1 | H23: RESISTOR | I23: SMD | J23: STACKPOLE | K23: CSR1206FK15L0 | L23: 15mΩ/0.5W | M23: 1206; ±1%; current sense
B24: FUNCTION | D24: - | F24: R_SET1 | G24: 1 | H24: RESISTOR | I24: SMD | J24: VISHAY | K24: CRCW0402301RFKED | L24: 301Ω/63mW | M24: 0402
B25: BIN OF LED | C25: BRIGHTNESS | D25: - | F25: R1 | G25: 1 | H25: RESISTOR | I25: SMD | J25: NOT SPECIFIED | K25: NOT SPECIFIED | L25: 100kΩ/0.1W | M25: 0603 (1608); ±1%; MPN not specified
C26: WAVELENGTH | D26: - | F26: R2, R6 | G26: 2 | H26: RESISTOR | I26: SMD | J26: PANASONIC | K26: ERJ2GE0R00X | L26: 0Ω/100mW | M26: 0402 (1005); -55 to +155°C; RoHS
C27: FORWARD VOLTAGE | D27: - | F27: R3 | G27: 1 | H27: RESISTOR | I27: SMD | J27: YAGEO | K27: AC0402FR-7W20KL | L27: 20kΩ/125mW | M27: 0402
B28: NOTE | D28: - | F28: R4 | G28: 1 | H28: RESISTOR | I28: SMD | J28: YAGEO | K28: RC0402FR-075KL | L28: 5kΩ/62.5mW | M28: 0402
F29: R5 | G29: 1 | H29: RESISTOR | I29: SMD | J29: PANASONIC | K29: ERJ2RKF4992X | L29: 49.9kΩ/100mW | M29: 0402
B30: ITEMS | D30: CONTENTS | F30: R7 | G30: 1 | H30: RESISTOR | I30: SMD | J30: VISHAY | K30: CRCW040211K8FKEE | L30: 11.8kΩ/63mW | M30: 0402
B31: STYLE | D31: - | F31: TVS1 | G31: 1 | H31: TVS DIODE | I31: SMD | J31: BOURNS | K31: SMBJ18CA-Q | L31: - | M31: Rating not specified in source
B32: MANUFACTURER | D32: - | F32: U1 | G32: 1 | H32: MOSFET | I32: SMD | J32: VISHAY | K32: SQ4917CEY-T1_GE3 | L32: 60V/8A | M32: SOIC-8; dual P-channel; 48mΩ
B33: PART NUMBER | D33: - | F33: U2 | G33: 1 | H33: USB INTERFACE IC | I33: SMD | J33: TEXAS INSTRUMENTS | K33: TPS25833QWRHBRQ1 | L33: 5V/3.5A | M33: VQFN-32; VIN 36V; Type-C/BC1.2
B34: TOTAL QUANTITY | D34: - | F34: ZD1 | G34: 1 | H34: ZENER DIODE | I34: SMD | J34: DIODES INC. | K34: BZT52C12Q-7-F | L34: 12V/370mW | M34: SOD-123; ±5.42%
B35: FUNCTION | D35: -
B36: BIN OF LED | C36: BRIGHTNESS | D36: -
C37: WAVELENGTH | D37: -
C38: FORWARD VOLTAGE | D38: -
B39: NOTE | D39: -
B42: 2. PCB SPEC
B43: ITEMS | D43: CONTENTS
...

Sheet Appendix
B1: APPENDIX | G1: PRODUCT NAME | H1: ='CIRCUIT SPECIFICATION'!H1:H3 -> HONDA MMCA BSI | I1: REVISION | K1: ='CIRCUIT SPECIFICATION'!K1 -> Rev.09 | L1: APPROVED BY | M1: CHECKED BY | N1: ISSUED BY
I2: ISSUED BY | K2: AMPAS R&D | L2: K.Imabeppu | M2: Krissada C. | N2: ='CIRCUIT SPECIFICATION'!N2:N5 -> Rattakiat Ch.
I3: ISSUE DATE | K3: ='CIRCUIT SPECIFICATION'!K3 -> 46262
B4: Contents in this sheet is under consideration. Circuit spec have possibility to change. | I4: NAME | K4: CIRCUIT ASSY
I5: PURPOSE | K5: ESTIMATION
F106: Confidential : Property of AMPAS R&D Co.,Ltd. - Duplication prohibited | N106: P.1/1

Sheet ESTIMATE COST
B1: ESTIMATE COST | I1: PRODUCT NAME | J1: ='CIRCUIT SPECIFICATION'!H1:H3 -> HONDA MMCA BSI | N1: REVISION | P1: ='CIRCUIT SPECIFICATION'!K1 -> Rev.09 | R1: APPROVED BY | S1: CHECKED BY | T1: ISSUED BY
N2: ISSUED BY | P2: AMPAS R&D | R2: K.Imabeppu | S2: Krissada C. | T2: ='CIRCUIT SPECIFICATION'!N2:N5 -> Rattakiat Ch.
N3: ISSUE DATE | P3: ='CIRCUIT SPECIFICATION'!K3 -> 46262
B4: Contents in this sheet is under consideration. Circuit spec have possibility to change. | N4: NAME | P4: CIRCUIT ASSY | W4: Mounted
N5: PURPOSE | P5: ESTIMATION | W5: Alternative
B8: No | C8: PART NAME | D8: MAKER | E8: MODEL NO. | F8: RATED VALUE | G8: LEAD TYPE | H8: REFERENCE | I8: Usage | J8: SUPPLIER | K8: PART NAME | N8: LT/DAY | O8: MOQ | P8: SPQ | Q8: CURRENCY | R8: PRICE | S8: REMARK | T8: KIT
B9: PCB1
B10: 1 | C10: ='CIRCUIT SPECIFICATION'!H10 -> LED | D10: ='CIRCUIT SPECIFICATION'!J10 -> OSRAM | E10: ='CIRCUIT SPECIFICATION'!K10 -> KY DDLN31.FY-5H8H-5F-8E8G-150-R18 | F10: ='CIRCUIT SPECIFICATION'!L10 -> 3.25V/200mA | G10: ='CIRCUIT SPECIFICATION'!I10 -> SMD | H10: ='CIRCUIT SPECIFICATION'!F10 -> LED1 - LED3 | I10: ='CIRCUIT SPECIFICATION'!G10 -> 3 | K10: =I10*#REF! -> #REF! | Q10: USD | R10: 0.14249 | S10: Mounted | T10: =R10*I10 -> 0.42747
B11: 2 | C11: ='CIRCUIT SPECIFICATION'!H11 -> CAPACITOR | D11: ='CIRCUIT SPECIFICATION'!J11 -> KEMET | E11: ='CIRCUIT SPECIFICATION'!K11 -> C0805C104M5RACAUTO | F11: ='CIRCUIT SPECIFICATION'!L11 -> 0.1uF/50V | G11: ='CIRCUIT SPECIFICATION'!I11 -> SMD | H11: ='CIRCUIT SPECIFICATION'!F11 -> C1, C2 | I11: ='CIRCUIT SPECIFICATION'!G11 -> 2 | K11: =I11*#REF! -> #REF! | Q11: THB | R11: 0.646 | S11: Mounted | T11: =R11*I11 -> 1.292
D12: ='CIRCUIT SPECIFICATION'!J12 -> YAGEO | E12: ='CIRCUIT SPECIFICATION'!K12 -> AC0805KRX7R9BB104 | I12: 0 | K12: =I12*#REF! -> #REF! | Q12: THB | R12: 0.937 | S12: Alternative | T12: =R12*I12 -> 0
D13: ='CIRCUIT SPECIFICATION'!J13 -> KYOCERA AVX | E13: ='CIRCUIT SPECIFICATION'!K13 -> 08055C104K4T4A | I13: 0 | K13: =I13*#REF! -> #REF! | Q13: THB | R13: 0.743 | S13: Alternative | T13: =R13*I13 -> 0
B14: 3 | C14: ='CIRCUIT SPECIFICATION'!H14 -> DIODE | D14: ='CIRCUIT SPECIFICATION'!J14 -> DIOTEC | E14: ='CIRCUIT SPECIFICATION'!K14 -> SL1J-AQ | F14: ='CIRCUIT SPECIFICATION'!L14 -> 600V/1A | G14: ='CIRCUIT SPECIFICATION'!I14 -> SMD | H14: ='CIRCUIT SPECIFICATION'!F14 -> D1 | I14: ='CIRCUIT SPECIFICATION'!G14 -> 1 | K14: =I14*#REF! -> #REF! | Q14: THB | R14: 0.788 | S14: Mounted | T14: =R14*I14 -> 0.788
B15: 4 | C15: ='CIRCUIT SPECIFICATION'!H15 -> RESISTOR | D15: ='CIRCUIT SPECIFICATION'!J15 -> ROHM | E15: ='CIRCUIT SPECIFICATION'!K15 -> LTR18EZPJ000 | F15: ='CIRCUIT SPECIFICATION'!L15 -> 0Ω/1W | G15: ='CIRCUIT SPECIFICATION'!I15 -> SMD | H15: ='CIRCUIT SPECIFICATION'!F15 -> R1 | I15: 1 | K15: =I15*#REF! -> #REF! | Q15: USD | R15: 0.02815 | S15: Mounted | T15: =R15*I15 -> 0.02815
D16: ='CIRCUIT SPECIFICATION'!J16 -> VISHAY | E16: ='CIRCUIT SPECIFICATION'!K16 -> RCL06120000Z0EA | I16: 0 | K16: =I16*#REF! -> #REF! | Q16: USD | R16: 0.0427 | S16: Alternative | T16: =R16*I16 -> 0
B17: 5 | C17: ='CIRCUIT SPECIFICATION'!H17 -> RESISTOR | D17: ='CIRCUIT SPECIFICATION'!J17 -> ROHM | E17: ='CIRCUIT SPECIFICATION'!K17 -> LTR18EZPJ000 | F17: ='CIRCUIT SPECIFICATION'!L17 -> 0Ω/1W | G17: ='CIRCUIT SPECIFICATION'!I17 -> SMD | H17: ='CIRCUIT SPECIFICATION'!F17 -> (R2) | I17: 0 | K17: =I17*#REF! -> #REF! | Q17: USD | R17: 0.02815 | S17: Alternative | T17: =R17*I17 -> 0
D18: ='CIRCUIT SPECIFICATION'!J18 -> VISHAY | E18: ='CIRCUIT SPECIFICATION'!K18 -> RCL06120000Z0EA | I18: ='CIRCUIT SPECIFICATION'!G18 -> 0 | K18: =I18*#REF! -> #REF! | Q18: USD | R18: 0.0427 | S18: Mounted | T18: =R18*I18 -> 0
B19: 6 | C19: ='CIRCUIT SPECIFICATION'!H19 -> PCB BOARD | D19: ='CIRCUIT SPECIFICATION'!J19 -> ANY | E19: ='CIRCUIT SPECIFICATION'!K19 -> FR4 (SIZE TBD) | F19: ='CIRCUIT SPECIFICATION'!L19 -> 130-150C | G19: ='CIRCUIT SPECIFICATION'!I19 -> - | H19: ='CIRCUIT SPECIFICATION'!F19 -> PCB | I19: ='CIRCUIT SPECIFICATION'!G19 -> 1 | Q19: USD | R19: 0.206536 | S19: Mounted | T19: =IF(S19=$W$4,R19*I19,0) -> 0.206536
B20: 7 | C20: ='CIRCUIT SPECIFICATION'!H20 -> WIRE HARNESS | D20: ='CIRCUIT SPECIFICATION'!J20 -> ANY | E20: ='CIRCUIT SPECIFICATION'!K20 -> AESSX 0.5f | F20: ='CIRCUIT SPECIFICATION'!L20 -> - | G20: ='CIRCUIT SPECIFICATION'!I20 -> INSERT | H20: ='CIRCUIT SPECIFICATION'!F20 -> T1, T2 | I20: ='CIRCUIT SPECIFICATION'!G20 -> 2 | Q20: THB | R20: 1 | S20: Mounted | T20: =IF(S20=$W$4,R20*I20,0) -> 2
Q21: THB | S21: Alternative | T21: =IF(S21=$W$4,R21*I21,0) -> 0
Q22: THB | S22: Alternative | T22: =IF(S22=$W$4,R22*I22,0) -> 0
Q23: THB | S23: Alternative | T23: =IF(S23=$W$4,R23*I23,0) -> 0
Q24: THB | S24: Alternative | T24: =IF(S24=$W$4,R24*I24,0) -> 0
Q25: THB | S25: Alternative | T25: =IF(S25=$W$4,R25*I25,0) -> 0
Q26: THB | S26: Alternative | T26: =IF(S26=$W$4,R26*I26,0) -> 0
Q27: THB | S27: Alternative | T27: =IF(S27=$W$4,R27*I27,0) -> 0
Q28: THB | S28: Alternative | T28: =IF(S28=$W$4,R28*I28,0) -> 0
Q29: THB | S29: Alternative | T29: =IF(S29=$W$4,R29*I29,0) -> 0
Q30: THB | S30: Alternative | T30: =IF(S30=$W$4,R30*I30,0) -> 0
Q31: THB | S31: Alternative | T31: =IF(S31=$W$4,R31*I31,0) -> 0
Q32: THB | S32: Alternative | T32: =IF(S32=$W$4,R32*I32,0) -> 0
... Q43: THB | S43: Alternative | T43: =IF(S43=$W$4,R43*I43,0) -> 0
L44: =SUM(L9:L41) -> 0 | Q44: THB | S44: Alternative | T44: =IF(S44=$W$4,R44*I44,0) -> 0
L45: =L44*0.25 -> 0 | Q45: THB | S45: Alternative | T45: =IF(S45=$W$4,R45*I45,0) -> 0
L46: 15 | Q46: THB | S46: Alternative | T46: =IF(S46=$W$4,R46*I46,0) -> 0
H49: Estimate | I49: =SUM(I12:I46)*0.1 -> 0.5 | J49: Shot Assy' | Q49: Currency Ratio | R49: USD = THB | S49: USD | T49: =SUMIFS(T9:T46,Q9:Q46,"=USD",S9:S46,"=Mounted") -> 0.662156
I50: =I49*0.5 -> 0.25 | J50: Submat | R50: 32.59 | S50: THB | T50: =T49*R50 -> 21.579664
I51: 1 | J51: Terminal soldering | R51: JPY = THB | S51: JPY | T51: =SUMIFS(T9:T46,Q9:Q46,"=JPY",S9:S46,"=Mounted") -> 0
I52: 2 | J52: Package & Transport | R52: 0.29983 | S52: THB | T52: =T51*R52 -> 0
H53: Total | I53: =SUM(I49:I52) -> 3.75 | S53: THB | T53: =SUMIFS(T8:T46,Q8:Q46,"=THB",S8:S46,"=Mounted") -> 4.08
R55: Material Cost | T55: =T50+T52+T53 -> 25.659664
...
